<robot name= "xarm7">
    <link name="base_link">
        <visual>
            <geometry>
                <mesh filename="package://xarm7_description/meshes/link_base.stl" scale="1.0 1.0 1.0"/>
            </geometry>   
        </visual>
    </link>

    <link name="link1">
        <visual>
            <geometry>
                <mesh filename="package://xarm7_description/meshes/link1.stl" scale="1.0 1.0 1.0"/>
            </geometry>   
        </visual>
    </link>

    <joint name="joint1" type="revolute">
        <parent link="base_link"/>
        <child link="link1"/>
        <origin xyz="0 0 0.267" rpy="0 0 0"/>
        <axis xyz="0 0 1"/>
        <limit lower="-6.283" upper="6.283" effort="50" velocity="3.142"/>
    </joint>

    <link name="link2">
        <visual>
            <geometry>
                <mesh filename="package://xarm7_description/meshes/link2.stl" scale="1.0 1.0 1.0"/>
            </geometry>
        </visual>
    </link>

    <joint name="joint2" type="revolute">
        <parent link="link1"/>
        <child link="link2"/>
        <origin xyz="0 0 0" rpy="-1.5708 0.0 0.0"/>
        <axis xyz="0 0 1"/>
        <limit lower="-2.059" upper="2.094" effort="50" velocity="3.142"/>
    </joint>

    <link name="link3">
        <visual>
            <geometry>
                <mesh filename="package://xarm7_description/meshes/link3.stl" scale="1.0 1.0 1.0"/>
            </geometry>
        </visual>
    </link>

    <joint name="joint3" type="revolute">
        <parent link="link2"/>
        <child link="link3"/>
        <origin xyz="0 -0.293 0" rpy="1.5708 0 0"/>
        <axis xyz="0 0 1"/>
        <limit lower="-6.283" upper="6.283" effort="50" velocity="3.142"/>
    </joint>

    <link name="link4">
        <visual>
            <geometry>
                <mesh filename="package://xarm7_description/meshes/link4.stl" scale="1.0 1.0 1.0"/>
            </geometry>
        </visual>
    </link>

    <joint name="joint4" type="revolute">
        <parent link="link3"/>
        <child link="link4"/>
        <origin xyz="0.0525 0 0" rpy="1.5708 0 0"/>
        <axis xyz="0 0 1"/>
        <limit lower="-0.192" upper="3.927" effort="50" velocity="3.142"/>
    </joint>

    <link name="link5">
        <visual>
            <geometry>
                <mesh filename="package://xarm7_description/meshes/link5.stl" scale="1.0 1.0 1.0"/>
            </geometry>
        </visual>
    </link>

    <joint name="joint5" type="revolute">
        <parent link="link4"/>
        <child link="link5"/>
        <origin xyz="0.0775 -0.3425 0" rpy="1.5708 0 0"/>
        <axis xyz="0 0 1"/>
        <limit lower="-6.283" upper="6.283" effort="50" velocity="3.142"/>
    </joint>

    <link name="link6">
        <visual>
            <geometry>
                <mesh filename="package://xarm7_description/meshes/link6.stl" scale="1.0 1.0 1.0"/>
            </geometry>
        </visual>
    </link>

    <joint name="joint6" type="revolute">
        <parent link="link5"/>
        <child link="link6"/>
        <origin xyz="0 0 0" rpy="1.5708 0 0"/>
        <axis xyz="0 0 1"/>
        <limit lower="-1.693" upper="3.142" effort="50" velocity="3.142"/>
    </joint>

    <link name="link7">
        <visual>
            <geometry>
                <mesh filename="package://xarm7_description/meshes/link7.stl" scale="1.0 1.0 1.0"/>
            </geometry>
        </visual>
    </link>

    <joint name="joint7" type="revolute">
        <parent link="link6"/>
        <child link="link7"/>
        <origin xyz="0.076 0.097 0" rpy="-1.5708 0 0"/>
        <axis xyz="0 0 1"/>
        <limit lower="-6.283" upper="6.283" effort="50" velocity="3.142"/>
    </joint>

    <link name="gripper">
        <visual>
            <geometry>
                <mesh filename="package://xarm7_description/meshes/gripper_lite.stl" scale="1.0 1.0 1.0"/>
            </geometry>
        </visual>
    </link>

    <joint name="joint8" type="fixed">
        <parent link="link7"/>
        <child link="gripper"/>
        <origin xyz="0 0 0" rpy="0 0 0"/>
        <axis xyz="0 0 1"/>
        <limit lower="-6.283" upper="6.283" effort="50" velocity="3.142"/>
    </joint>
</robot>